2025-03-20 10:40:20,280 - app - ERROR - Failed to start server: (psycopg2.ProgrammingError) invalid dsn: invalid connection option "timeout" (Background on this error at: https://sqlalche.me/e/20/f405) [2025-03-20 10:40:20 +0000] [2347] [ERROR] Exception in worker process Traceback (most recent call last): File "/home/runner/workspace/.pythonlibs/lib/python3.11/site-packages/sqlalchemy/engine/base.py", line 146, in __init__ self._dbapi_connection = engine.raw_connection() ^^^^^^^^^^^^^^^^^^^^^^^ File "/home/runner/workspace/.pythonlibs/lib/python3.11/site-packages/sqlalchemy/engine/base.py", line 3298, in raw_connection return self.pool.connect() ^^^^^^^^^^^^^^^^^^^ File "/home/runner/workspace/.pythonlibs/lib/python3.11/site-packages/sqlalchemy/pool/base.py", line 449, in connect return _ConnectionFairy._checkout(self) ^^^^^^^^^^^^^^^^^^^^^^^^^^^^^^^^ File "/home/runner/workspace/.pythonlibs/lib/python3.11/site-packages/sqlalchemy/pool/base.py", line 1263, in _checkout fairy = _ConnectionRecord.checkout(pool) ^^^^^^^^^^^^^^^^^^^^^^^^^^^^^^^^ File "/home/runner/workspace/.pythonlibs/lib/python3.11/site-packages/sqlalchemy/pool/base.py", line 712, in checkout rec = pool._do_get() ^^^^^^^^^^^^^^ File "/home/runner/workspace/.pythonlibs/lib/python3.11/site-packages/sqlalchemy/pool/impl.py", line 179, in _do_get with util.safe_reraise(): File "/home/runner/workspace/.pythonlibs/lib/python3.11/site-packages/sqlalchemy/util/langhelpers.py", line 146, in __exit__ raise exc_value.with_traceback(exc_tb) File "/home/runner/workspace/.pythonlibs/lib/python3.11/site-packages/sqlalchemy/pool/impl.py", line 177, in _do_get return self._create_connection() ^^^^^^^^^^^^^^^^^^^^^^^^^ File "/home/runner/workspace/.pythonlibs/lib/python3.11/site-packages/sqlalchemy/pool/base.py", line 390, in _create_connection return _ConnectionRecord(self) ^^^^^^^^^^^^^^^^^^^^^^^ File "/home/runner/workspace/.pythonlibs/lib/python3.11/site-packages/sqlalchemy/pool/base.py", line 674, in __init__ self.__connect() File "/home/runner/workspace/.pythonlibs/lib/python3.11/site-packages/sqlalchemy/pool/base.py", line 900, in __connect with util.safe_reraise(): File "/home/runner/workspace/.pythonlibs/lib/python3.11/site-packages/sqlalchemy/util/langhelpers.py", line 146, in __exit__ raise exc_value.with_traceback(exc_tb) File "/home/runner/workspace/.pythonlibs/lib/python3.11/site-packages/sqlalchemy/pool/base.py", line 896, in __connect self.dbapi_connection = connection = pool._invoke_creator(self) ^^^^^^^^^^^^^^^^^^^^^^^^^^ File "/home/runner/workspace/.pythonlibs/lib/python3.11/site-packages/sqlalchemy/engine/create.py", line 646, in connect return dialect.connect(*cargs, **cparams) ^^^^^^^^^^^^^^^^^^^^^^^^^^^^^^^^^^ File "/home/runner/workspace/.pythonlibs/lib/python3.11/site-packages/sqlalchemy/engine/default.py", line 622, in connect return self.loaded_dbapi.connect(*cargs, **cparams) ^^^^^^^^^^^^^^^^^^^^^^^^^^^^^^^^^^^^^^^^^^^^ File "/home/runner/workspace/.pythonlibs/lib/python3.11/site-packages/psycopg2/__init__.py", line 121, in connect dsn = _ext.make_dsn(dsn, **kwargs) ^^^^^^^^^^^^^^^^^^^^^^^^^^^^ File "/home/runner/workspace/.pythonlibs/lib/python3.11/site-packages/psycopg2/extensions.py", line 167, in make_dsn parse_dsn(dsn) psycopg2.ProgrammingError: invalid dsn: invalid connection option "timeout" The above exception was the direct cause of the following exception: Traceback (most recent call last): File "/home/runner/workspace/.pythonlibs/lib/python3.11/site-packages/gunicorn/arbiter.py", line 608, in spawn_worker worker.init_process() File "/home/runner/workspace/.pythonlibs/lib/python3.11/site-packages/gunicorn/workers/base.py", line 135, in init_process self.load_wsgi() File "/home/runner/workspace/.pythonlibs/lib/python3.11/site-packages/gunicorn/workers/base.py", line 147, in load_wsgi self.wsgi = self.app.wsgi() ^^^^^^^^^^^^^^^ File "/home/runner/workspace/.pythonlibs/lib/python3.11/site-packages/gunicorn/app/base.py", line 66, in wsgi self.callable = self.load() ^^^^^^^^^^^ File "/home/runner/workspace/.pythonlibs/lib/python3.11/site-packages/gunicorn/app/wsgiapp.py", line 57, in load return self.load_wsgiapp() ^^^^^^^^^^^^^^^^^^^ File "/home/runner/workspace/.pythonlibs/lib/python3.11/site-packages/gunicorn/app/wsgiapp.py", line 47, in load_wsgiapp return util.import_app(self.app_uri) ^^^^^^^^^^^^^^^^^^^^^^^^^^^^^ File "/home/runner/workspace/.pythonlibs/lib/python3.11/site-packages/gunicorn/util.py", line 370, in import_app mod = importlib.import_module(module) ^^^^^^^^^^^^^^^^^^^^^^^^^^^^^^^ File "/nix/store/clx0mcir7qw8zk36zbr4jra789g3knf6-python3-3.11.10/lib/python3.11/importlib/__init__.py", line 126, in import_module return _bootstrap._gcd_import(name[level:], package, level) ^^^^^^^^^^^^^^^^^^^^^^^^^^^^^^^^^^^^^^^^^^^^^^^^^^^^ File "<frozen importlib._bootstrap>", line 1204, in _gcd_import File "<frozen importlib._bootstrap>", line 1176, in _find_and_load File "<frozen importlib._bootstrap>", line 1147, in _find_and_load_unlocked File "<frozen importlib._bootstrap>", line 690, in _load_unlocked File "<frozen importlib._bootstrap_external>", line 940, in exec_module File "<frozen importlib._bootstrap>", line 241, in _call_with_frames_removed File "/home/runner/workspace/main.py", line 2, in <module> from app import app, db, logger File "/home/runner/workspace/app.py", line 110, in <module> db.create_all() File "/home/runner/workspace/.pythonlibs/lib/python3.11/site-packages/flask_sqlalchemy/extension.py", line 900, in create_all self._call_for_binds(bind_key, "create_all") File "/home/runner/workspace/.pythonlibs/lib/python3.11/site-packages/flask_sqlalchemy/extension.py", line 881, in _call_for_binds getattr(metadata, op_name)(bind=engine) File "/home/runner/workspace/.pythonlibs/lib/python3.11/site-packages/sqlalchemy/sql/schema.py", line 5907, in create_all bind._run_ddl_visitor( File "/home/runner/workspace/.pythonlibs/lib/python3.11/site-packages/sqlalchemy/engine/base.py", line 3248, in _run_ddl_visitor with self.begin() as conn: File "/nix/store/clx0mcir7qw8zk36zbr4jra789g3knf6-python3-3.11.10/lib/python3.11/contextlib.py", line 137, in __enter__ return next(self.gen) ^^^^^^^^^^^^^^ File "/home/runner/workspace/.pythonlibs/lib/python3.11/site-packages/sqlalchemy/engine/base.py", line 3238, in begin with self.connect() as conn: ^^^^^^^^^^^^^^ File "/home/runner/workspace/.pythonlibs/lib/python3.11/site-packages/sqlalchemy/engine/base.py", line 3274, in connect return self._connection_cls(self) ^^^^^^^^^^^^^^^^^^^^^^^^^^ File "/home/runner/workspace/.pythonlibs/lib/python3.11/site-packages/sqlalchemy/engine/base.py", line 148, in __init__ Connection._handle_dbapi_exception_noconnection( File "/home/runner/workspace/.pythonlibs/lib/python3.11/site-packages/sqlalchemy/engine/base.py", line 2439, in _handle_dbapi_exception_noconnection raise sqlalchemy_exception.with_traceback(exc_info[2]) from e File "/home/runner/workspace/.pythonlibs/lib/python3.11/site-packages/sqlalchemy/engine/base.py", line 146, in __init__ self._dbapi_connection = engine.raw_connection() ^^^^^^^^^^^^^^^^^^^^^^^ File "/home/runner/workspace/.pythonlibs/lib/python3.11/site-packages/sqlalchemy/engine/base.py", line 3298, in raw_connection return self.pool.connect() ^^^^^^^^^^^^^^^^^^^ File "/home/runner/workspace/.pythonlibs/lib/python3.11/site-packages/sqlalchemy/pool/base.py", line 449, in connect return _ConnectionFairy._checkout(self) ^^^^^^^^^^^^^^^^^^^^^^^^^^^^^^^^ File "/home/runner/workspace/.pythonlibs/lib/python3.11/site-packages/sqlalchemy/pool/base.py", line 1263, in _checkout fairy = _ConnectionRecord.checkout(pool) ^^^^^^^^^^^^^^^^^^^^^^^^^^^^^^^^ File "/home/runner/workspace/.pythonlibs/lib/python3.11/site-packages/sqlalchemy/pool/base.py", line 712, in checkout rec = pool._do_get() ^^^^^^^^^^^^^^ File "/home/runner/workspace/.pythonlibs/lib/python3.11/site-packages/sqlalchemy/pool/impl.py", line 179, in _do_get with util.safe_reraise(): File "/home/runner/workspace/.pythonlibs/lib/python3.11/site-packages/sqlalchemy/util/langhelpers.py", line 146, in __exit__ raise exc_value.with_traceback(exc_tb) File "/home/runner/workspace/.pythonlibs/lib/python3.11/site-packages/sqlalchemy/pool/impl.py", line 177, in _do_get return self._create_connection() ^^^^^^^^^^^^^^^^^^^^^^^^^ File "/home/runner/workspace/.pythonlibs/lib/python3.11/site-packages/sqlalchemy/pool/base.py", line 390, in _create_connection return _ConnectionRecord(self) ^^^^^^^^^^^^^^^^^^^^^^^ File "/home/runner/workspace/.pythonlibs/lib/python3.11/site-packages/sqlalchemy/pool/base.py", line 674, in __init__ self.__connect() File "/home/runner/workspace/.pythonlibs/lib/python3.11/site-packages/sqlalchemy/pool/base.py", line 900, in __connect with util.safe_reraise(): File "/home/runner/workspace/.pythonlibs/lib/python3.11/site-packages/sqlalchemy/util/langhelpers.py", line 146, in __exit__ raise exc_value.with_traceback(exc_tb) File "/home/runner/workspace/.pythonlibs/lib/python3.11/site-packages/sqlalchemy/pool/base.py", line 896, in __connect self.dbapi_connection = connection = pool._invoke_creator(self) ^^^^^^^^^^^^^^^^^^^^^^^^^^ File "/home/runner/workspace/.pythonlibs/lib/python3.11/site-packages/sqlalchemy/engine/create.py", line 646, in connect return dialect.connect(*cargs, **cparams) ^^^^^^^^^^^^^^^^^^^^^^^^^^^^^^^^^^ File "/home/runner/workspace/.pythonlibs/lib/python3.11/site-packages/sqlalchemy/engine/default.py", line 622, in connect return self.loaded_dbapi.connect(*cargs, **cparams) ^^^^^^^^^^^^^^^^^^^^^^^^^^^^^^^^^^^^^^^^^^^^ File "/home/runner/workspace/.pythonlibs/lib/python3.11/site-packages/psycopg2/__init__.py", line 121, in connect dsn = _ext.make_dsn(dsn, **kwargs) ^^^^^^^^^^^^^^^^^^^^^^^^^^^^ File "/home/runner/workspace/.pythonlibs/lib/python3.11/site-packages/psycopg2/extensions.py", line 167, in make_dsn parse_dsn(dsn) sqlalchemy.exc.ProgrammingError: (psycopg2.ProgrammingError) invalid dsn: invalid connection option "timeout" (Background on this error at: https://sqlalche.me/e/20/f405) [2025-03-20 10:40:20 +0000] [2347] [INFO] Worker exiting (pid: 2347) 2025-03-20 10:40:20,320 - app - ERROR - Failed to start server: (psycopg2.ProgrammingError) invalid dsn: invalid connection option "timeout" (Background on this error at: https://sqlalche.me/e/20/f405) [2025-03-20 10:40:20 +0000] [2348] [ERROR] Exception in worker process Traceback (most recent call last): File "/home/runner/workspace/.pythonlibs/lib/python3.11/site-packages/sqlalchemy/engine/base.py", line 146, in __init__ self._dbapi_connection = engine.raw_connection() ^^^^^^^^^^^^^^^^^^^^^^^ File "/home/runner/workspace/.pythonlibs/lib/python3.11/site-packages/sqlalchemy/engine/base.py", line 3298, in raw_connection return self.pool.connect() ^^^^^^^^^^^^^^^^^^^ File "/home/runner/workspace/.pythonlibs/lib/python3.11/site-packages/sqlalchemy/pool/base.py", line 449, in connect return _ConnectionFairy._checkout(self) ^^^^^^^^^^^^^^^^^^^^^^^^^^^^^^^^ File "/home/runner/workspace/.pythonlibs/lib/python3.11/site-packages/sqlalchemy/pool/base.py", line 1263, in _checkout fairy = _ConnectionRecord.checkout(pool) ^^^^^^^^^^^^^^^^^^^^^^^^^^^^^^^^ File "/home/runner/workspace/.pythonlibs/lib/python3.11/site-packages/sqlalchemy/pool/base.py", line 712, in checkout rec = pool._do_get() ^^^^^^^^^^^^^^ File "/home/runner/workspace/.pythonlibs/lib/python3.11/site-packages/sqlalchemy/pool/impl.py", line 179, in _do_get with util.safe_reraise(): File "/home/runner/workspace/.pythonlibs/lib/python3.11/site-packages/sqlalchemy/util/langhelpers.py", line 146, in __exit__ raise exc_value.with_traceback(exc_tb) File "/home/runner/workspace/.pythonlibs/lib/python3.11/site-packages/sqlalchemy/pool/impl.py", line 177, in _do_get return self._create_connection() ^^^^^^^^^^^^^^^^^^^^^^^^^ File "/home/runner/workspace/.pythonlibs/lib/python3.11/site-packages/sqlalchemy/pool/base.py", line 390, in _create_connection return _ConnectionRecord(self) ^^^^^^^^^^^^^^^^^^^^^^^ File "/home/runner/workspace/.pythonlibs/lib/python3.11/site-packages/sqlalchemy/pool/base.py", line 674, in __init__ self.__connect() File "/home/runner/workspace/.pythonlibs/lib/python3.11/site-packages/sqlalchemy/pool/base.py", line 900, in __connect with util.safe_reraise(): File "/home/runner/workspace/.pythonlibs/lib/python3.11/site-packages/sqlalchemy/util/langhelpers.py", line 146, in __exit__ raise exc_value.with_traceback(exc_tb) File "/home/runner/workspace/.pythonlibs/lib/python3.11/site-packages/sqlalchemy/pool/base.py", line 896, in __connect self.dbapi_connection = connection = pool._invoke_creator(self) ^^^^^^^^^^^^^^^^^^^^^^^^^^ File "/home/runner/workspace/.pythonlibs/lib/python3.11/site-packages/sqlalchemy/engine/create.py", line 646, in connect return dialect.connect(*cargs, **cparams) ^^^^^^^^^^^^^^^^^^^^^^^^^^^^^^^^^^ File "/home/runner/workspace/.pythonlibs/lib/python3.11/site-packages/sqlalchemy/engine/default.py", line 622, in connect return self.loaded_dbapi.connect(*cargs, **cparams) ^^^^^^^^^^^^^^^^^^^^^^^^^^^^^^^^^^^^^^^^^^^^ File "/home/runner/workspace/.pythonlibs/lib/python3.11/site-packages/psycopg2/__init__.py", line 121, in connect dsn = _ext.make_dsn(dsn, **kwargs) ^^^^^^^^^^^^^^^^^^^^^^^^^^^^ File "/home/runner/workspace/.pythonlibs/lib/python3.11/site-packages/psycopg2/extensions.py", line 167, in make_dsn parse_dsn(dsn) psycopg2.ProgrammingError: invalid dsn: invalid connection option "timeout" The above exception was the direct cause of the following exception: Traceback (most recent call last): File "/home/runner/workspace/.pythonlibs/lib/python3.11/site-packages/gunicorn/arbiter.py", line 608, in spawn_worker worker.init_process() File "/home/runner/workspace/.pythonlibs/lib/python3.11/site-packages/gunicorn/workers/base.py", line 135, in init_process self.load_wsgi() File "/home/runner/workspace/.pythonlibs/lib/python3.11/site-packages/gunicorn/workers/base.py", line 147, in load_wsgi self.wsgi = self.app.wsgi() ^^^^^^^^^^^^^^^ File "/home/runner/workspace/.pythonlibs/lib/python3.11/site-packages/gunicorn/app/base.py", line 66, in wsgi self.callable = self.load() ^^^^^^^^^^^ File "/home/runner/workspace/.pythonlibs/lib/python3.11/site-packages/gunicorn/app/wsgiapp.py", line 57, in load return self.load_wsgiapp() ^^^^^^^^^^^^^^^^^^^ File "/home/runner/workspace/.pythonlibs/lib/python3.11/site-packages/gunicorn/app/wsgiapp.py", line 47, in load_wsgiapp return util.import_app(self.app_uri) ^^^^^^^^^^^^^^^^^^^^^^^^^^^^^ File "/home/runner/workspace/.pythonlibs/lib/python3.11/site-packages/gunicorn/util.py", line 370, in import_app mod = importlib.import_module(module) ^^^^^^^^^^^^^^^^^^^^^^^^^^^^^^^ File "/nix/store/clx0mcir7qw8zk36zbr4jra789g3knf6-python3-3.11.10/lib/python3.11/importlib/__init__.py", line 126, in import_module return _bootstrap._gcd_import(name[level:], package, level) ^^^^^^^^^^^^^^^^^^^^^^^^^^^^^^^^^^^^^^^^^^^^^^^^^^^^ File "<frozen importlib._bootstrap>", line 1204, in _gcd_import File "<frozen importlib._bootstrap>", line 1176, in _find_and_load File "<frozen importlib._bootstrap>", line 1147, in _find_and_load_unlocked File "<frozen importlib._bootstrap>", line 690, in _load_unlocked File "<frozen importlib._bootstrap_external>", line 940, in exec_module File "<frozen importlib._bootstrap>", line 241, in _call_with_frames_removed File "/home/runner/workspace/main.py", line 2, in <module> from app import app, db, logger File "/home/runner/workspace/app.py", line 110, in <module> db.create_all() File "/home/runner/workspace/.pythonlibs/lib/python3.11/site-packages/flask_sqlalchemy/extension.py", line 900, in create_all self._call_for_binds(bind_key, "create_all") File "/home/runner/workspace/.pythonlibs/lib/python3.11/site-packages/flask_sqlalchemy/extension.py", line 881, in _call_for_binds getattr(metadata, op_name)(bind=engine) File "/home/runner/workspace/.pythonlibs/lib/python3.11/site-packages/sqlalchemy/sql/schema.py", line 5907, in create_all bind._run_ddl_visitor( File "/home/runner/workspace/.pythonlibs/lib/python3.11/site-packages/sqlalchemy/engine/base.py", line 3248, in _run_ddl_visitor with self.begin() as conn: File "/nix/store/clx0mcir7qw8zk36zbr4jra789g3knf6-python3-3.11.10/lib/python3.11/contextlib.py", line 137, in __enter__ return next(self.gen) ^^^^^^^^^^^^^^ File "/home/runner/workspace/.pythonlibs/lib/python3.11/site-packages/sqlalchemy/engine/base.py", line 3238, in begin with self.connect() as conn: ^^^^^^^^^^^^^^ File "/home/runner/workspace/.pythonlibs/lib/python3.11/site-packages/sqlalchemy/engine/base.py", line 3274, in connect return self._connection_cls(self) ^^^^^^^^^^^^^^^^^^^^^^^^^^ File "/home/runner/workspace/.pythonlibs/lib/python3.11/site-packages/sqlalchemy/engine/base.py", line 148, in __init__ Connection._handle_dbapi_exception_noconnection( File "/home/runner/workspace/.pythonlibs/lib/python3.11/site-packages/sqlalchemy/engine/base.py", line 2439, in _handle_dbapi_exception_noconnection raise sqlalchemy_exception.with_traceback(exc_info[2]) from e File "/home/runner/workspace/.pythonlibs/lib/python3.11/site-packages/sqlalchemy/engine/base.py", line 146, in __init__ self._dbapi_connection = engine.raw_connection() ^^^^^^^^^^^^^^^^^^^^^^^ File "/home/runner/workspace/.pythonlibs/lib/python3.11/site-packages/sqlalchemy/engine/base.py", line 3298, in raw_connection return self.pool.connect() ^^^^^^^^^^^^^^^^^^^ File "/home/runner/workspace/.pythonlibs/lib/python3.11/site-packages/sqlalchemy/pool/base.py", line 449, in connect return _ConnectionFairy._checkout(self) ^^^^^^^^^^^^^^^^^^^^^^^^^^^^^^^^ File "/home/runner/workspace/.pythonlibs/lib/python3.11/site-packages/sqlalchemy/pool/base.py", line 1263, in _checkout fairy = _ConnectionRecord.checkout(pool) ^^^^^^^^^^^^^^^^^^^^^^^^^^^^^^^^ File "/home/runner/workspace/.pythonlibs/lib/python3.11/site-packages/sqlalchemy/pool/base.py", line 712, in checkout rec = pool._do_get() ^^^^^^^^^^^^^^ File "/home/runner/workspace/.pythonlibs/lib/python3.11/site-packages/sqlalchemy/pool/impl.py", line 179, in _do_get with util.safe_reraise(): File "/home/runner/workspace/.pythonlibs/lib/python3.11/site-packages/sqlalchemy/util/langhelpers.py", line 146, in __exit__ raise exc_value.with_traceback(exc_tb) File "/home/runner/workspace/.pythonlibs/lib/python3.11/site-packages/sqlalchemy/pool/impl.py", line 177, in _do_get return self._create_connection() ^^^^^^^^^^^^^^^^^^^^^^^^^ File "/home/runner/workspace/.pythonlibs/lib/python3.11/site-packages/sqlalchemy/pool/base.py", line 390, in _create_connection return _ConnectionRecord(self) ^^^^^^^^^^^^^^^^^^^^^^^ File "/home/runner/workspace/.pythonlibs/lib/python3.11/site-packages/sqlalchemy/pool/base.py", line 674, in __init__ self.__connect() File "/home/runner/workspace/.pythonlibs/lib/python3.11/site-packages/sqlalchemy/pool/base.py", line 900, in __connect with util.safe_reraise(): File "/home/runner/workspace/.pythonlibs/lib/python3.11/site-packages/sqlalchemy/util/langhelpers.py", line 146, in __exit__ raise exc_value.with_traceback(exc_tb) File "/home/runner/workspace/.pythonlibs/lib/python3.11/site-packages/sqlalchemy/pool/base.py", line 896, in __connect self.dbapi_connection = connection = pool._invoke_creator(self) ^^^^^^^^^^^^^^^^^^^^^^^^^^ File "/home/runner/workspace/.pythonlibs/lib/python3.11/site-packages/sqlalchemy/engine/create.py", line 646, in connect return dialect.connect(*cargs, **cparams) ^^^^^^^^^^^^^^^^^^^^^^^^^^^^^^^^^^ File "/home/runner/workspace/.pythonlibs/lib/python3.11/site-packages/sqlalchemy/engine/default.py", line 622, in connect return self.loaded_dbapi.connect(*cargs, **cparams) ^^^^^^^^^^^^^^^^^^^^^^^^^^^^^^^^^^^^^^^^^^^^ File "/home/runner/workspace/.pythonlibs/lib/python3.11/site-packages/psycopg2/__init__.py", line 121, in connect dsn = _ext.make_dsn(dsn, **kwargs) ^^^^^^^^^^^^^^^^^^^^^^^^^^^^ File "/home/runner/workspace/.pythonlibs/lib/python3.11/site-packages/psycopg2/extensions.py", line 167, in make_dsn parse_dsn(dsn) sqlalchemy.exc.ProgrammingError: (psycopg2.ProgrammingError) invalid dsn: invalid connection option "timeout"